<?xml version="1.0"?>
<robot name="lrmate200ic5l_with_sg2">
  <link name="base_link">
    <visual>
      <origin rpy="0 0 0" xyz="0 0 0" />
      <geometry>
        <mesh filename="visual/base_link.stl" />
      </geometry>
      <material name="base_link_mat">
        <color rgba="0.23921568627450981 0.23921568627450981 0.23921568627450981 1.0" />
      </material>
    </visual>
    <collision>
      <origin rpy="0 0 0" xyz="0 0 0" />
      <geometry>
        <mesh filename="collision/base_link.stl" />
      </geometry>
    </collision>
    <inertial>
      <origin xyz="0 0 0" rpy="0 0 0" />
      <mass value="20.0" />
      <inertia ixx="1.0" ixy="0.0" ixz="0.0" iyy="1.0" iyz="0.0" izz="1.0" />
    </inertial>
  </link>

  <link name="link_1">
    <visual>
      <origin rpy="0 0 0" xyz="0 0 0" />
      <geometry>
        <mesh filename="visual/link_1.stl" />
      </geometry>
      <material name="link_1_mat">
        <color rgba="0.96 0.76 0.13 1.0" />
      </material>
    </visual>
    <collision>
      <origin rpy="0 0 0" xyz="0 0 0" />
      <geometry>
        <mesh filename="collision/link_1.stl" />
      </geometry>
    </collision>
    <inertial>
      <origin xyz="0 0 0" rpy="0 0 0" />
      <mass value="10.0" />
      <inertia ixx="1.0" ixy="0.0" ixz="0.0" iyy="1.0" iyz="0.0" izz="1.0" />
    </inertial>
  </link>

  <link name="link_2">
    <visual>
      <origin rpy="0 0 0" xyz="0 0 0" />
      <geometry>
        <mesh filename="visual/link_2.stl" />
      </geometry>
      <material name="link_2_mat">
        <color rgba="0.96 0.76 0.13 1.0" />
      </material>
    </visual>
    <collision>
      <origin rpy="0 0 0" xyz="0 0 0" />
      <geometry>
        <mesh filename="collision/link_2.stl" />
      </geometry>
    </collision>
    <inertial>
      <origin xyz="0 0 0" rpy="0 0 0" />
      <mass value="8.0" />
      <inertia ixx="1.0" ixy="0.0" ixz="0.0" iyy="1.0" iyz="0.0" izz="1.0" />
    </inertial>
  </link>

  <link name="link_3">
    <visual>
      <origin rpy="0 0 0" xyz="0 0 0" />
      <geometry>
        <mesh filename="visual/link_3.stl" />
      </geometry>
      <material name="link_3_mat">
        <color rgba="0.96 0.76 0.13 1.0" />
      </material>
    </visual>
    <collision>
      <origin rpy="0 0 0" xyz="0 0 0" />
      <geometry>
        <mesh filename="collision/link_3.stl" />
      </geometry>
    </collision>
    <inertial>
      <origin xyz="0 0 0" rpy="0 0 0" />
      <mass value="6.0" />
      <inertia ixx="1.0" ixy="0.0" ixz="0.0" iyy="1.0" iyz="0.0" izz="1.0" />
    </inertial>
  </link>

  <link name="link_4">
    <visual>
      <origin rpy="0 0 0" xyz="0 0 0" />
      <geometry>
        <mesh filename="visual/link_4.stl" />
      </geometry>
      <material name="link_4_mat">
        <color rgba="0.96 0.76 0.13 1.0" />
      </material>
    </visual>
    <collision>
      <origin rpy="0 0 0" xyz="0 0 0" />
      <geometry>
        <mesh filename="collision/link_4.stl" />
      </geometry>
    </collision>
    <inertial>
      <origin xyz="0 0 0" rpy="0 0 0" />
      <mass value="4.0" />
      <inertia ixx="1.0" ixy="0.0" ixz="0.0" iyy="1.0" iyz="0.0" izz="1.0" />
    </inertial>
  </link>

  <link name="link_5">
    <visual>
      <origin rpy="0 0 0" xyz="0 0 0" />
      <geometry>
        <mesh filename="visual/link_5.stl" />
      </geometry>
      <material name="link_5_mat">
        <color rgba="0.96 0.76 0.13 1.0" />
      </material>
    </visual>
    <collision>
      <origin rpy="0 0 0" xyz="0 0 0" />
      <geometry>
        <mesh filename="collision/link_5.stl" />
      </geometry>
    </collision>
    <inertial>
      <origin xyz="0 0 0" rpy="0 0 0" />
      <mass value="3.0" />
      <inertia ixx="1.0" ixy="0.0" ixz="0.0" iyy="1.0" iyz="0.0" izz="1.0" />
    </inertial>
  </link>

  <link name="link_6">
    <visual>
      <origin rpy="0 0 0" xyz="0 0 0" />
      <geometry>
        <mesh filename="visual/link_6.stl" />
      </geometry>
      <material name="link_6_mat">
        <color rgba="0.15 0.15 0.15 1.0" />
      </material>
    </visual>
    <collision>
      <origin rpy="0 0 0" xyz="0 0 0" />
      <geometry>
        <mesh filename="collision/link_6.stl" />
      </geometry>
    </collision>
    <inertial>
      <origin xyz="0 0 0" rpy="0 0 0" />
      <mass value="2.0" />
      <inertia ixx="1.0" ixy="0.0" ixz="0.0" iyy="1.0" iyz="0.0" izz="1.0" />
    </inertial>
  </link>

  <link name="flange" />
  <link name="tool0" />

  <link name="sg2">
    <visual>
      <origin rpy="0 0 0" xyz="0 0 0" />
      <geometry>
        <mesh filename="visual/sg2_reduced.stl" />
      </geometry>
      <material name="sg2_mat">
        <color rgba="0.5 0.5 0.5 1.0" />
      </material>
    </visual>
    <collision>
      <origin rpy="0 0 0" xyz="0 0 0" />
      <geometry>
        <mesh filename="collision/sg2_collision.stl" />
      </geometry>
    </collision>
    <inertial>
      <origin xyz="0 0 0" rpy="0 0 0" />
      <mass value="1.0" />
      <inertia ixx="0.005" ixy="0.0" ixz="0.0" iyy="0.005" iyz="0.0" izz="0.005" />
    </inertial>
  </link>

  <link name="tcp" />

  <joint name="joint_1" type="revolute">
    <origin rpy="0 0 0" xyz="0 0 0.330" />
    <parent link="base_link" />
    <child link="link_1" />
    <axis xyz="0 0 1" />
    <limit lower="-2.9671" upper="2.9671" effort="0" velocity="4.7124" />
  </joint>

  <joint name="joint_2" type="revolute">
    <origin rpy="0 0 0" xyz="0.075 0 0" />
    <parent link="link_1" />
    <child link="link_2" />
    <axis xyz="0 1 0" />
    <limit lower="-1.5708" upper="2.4435" effort="0" velocity="4.7124" />
  </joint>

  <joint name="joint_3" type="revolute">
    <origin rpy="0 0 0" xyz="0 0 0.400" />
    <parent link="link_2" />
    <child link="link_3" />
    <axis xyz="0 -1 0" />
    <limit lower="-2.5831" upper="4.0143" effort="0" velocity="4.7124" />
  </joint>

  <joint name="joint_4" type="revolute">
    <origin rpy="0 0 0" xyz="0 0 0.075" />
    <parent link="link_3" />
    <child link="link_4" />
    <axis xyz="-1 0 0" />
    <limit lower="-3.3161" upper="3.3161" effort="0" velocity="7.8540" />
  </joint>

  <joint name="joint_5" type="revolute">
    <origin rpy="0 0 0" xyz="0.410 0 0" />
    <parent link="link_4" />
    <child link="link_5" />
    <axis xyz="0 -1 0" />
    <limit lower="-2.0944" upper="2.0944" effort="0" velocity="7.8540" />
  </joint>

  <joint name="joint_6" type="revolute">
    <origin rpy="0 0 0" xyz="0.080 0 0" />
    <parent link="link_5" />
    <child link="link_6" />
    <axis xyz="-1 0 0" />
    <limit lower="-6.2832" upper="6.2832" effort="0" velocity="12.5664" />
  </joint>

  <joint name="joint_6_flange" type="fixed">
    <origin rpy="0 0 0" xyz="0 0 0" />
    <parent link="link_6" />
    <child link="flange" />
  </joint>

  <joint name="link_6_tool0" type="fixed">
    <origin rpy="3.141592653589793 -1.5707963267948966 0" xyz="0 0 0" />
    <parent link="flange" />
    <child link="tool0" />
  </joint>

  <joint name="sg2_joint" type="fixed">
    <origin rpy="0 0 0" xyz="0 0 0" />
    <parent link="tool0" />
    <child link="sg2" />
    <dont_collapse>true</dont_collapse>
  </joint>

  <joint name="tcp_joint" type="fixed">
    <origin rpy="0.523599 0.3926991 0" xyz="0.038715737 -0.040901752 0.200745221" />
    <parent link="sg2" />
    <child link="tcp" />
    <dont_collapse>true</dont_collapse>
  </joint>
</robot>
